<?xml version="1.0"?>
<robot xmlns:xacro="http://www.ros.org/wiki/xacro" name="mecanum_robot">

  <!-- Include materials -->
  <xacro:include filename="$(find mecanum_description)/urdf/materials.xacro"/>
  
  <!-- Robot parameters -->
  <xacro:property name="base_width" value="0.4"/>
  <xacro:property name="base_length" value="0.5"/>
  <xacro:property name="base_height" value="0.1"/>
  <xacro:property name="wheel_radius" value="0.1"/>
  <xacro:property name="wheel_width" value="0.05"/>
  <xacro:property name="wheel_offset_x" value="0.2"/>
  <xacro:property name="wheel_offset_y" value="0.225"/>
  
  <!-- Base link -->
  <link name="base_link">
    <visual>
      <origin xyz="0 0 0" rpy="0 0 0"/>
      <geometry>
        <box size="${base_length} ${base_width} ${base_height}"/>
      </geometry>
      <material name="blue"/>
    </visual>
    <collision>
      <origin xyz="0 0 0" rpy="0 0 0"/>
      <geometry>
        <box size="${base_length} ${base_width} ${base_height}"/>
      </geometry>
    </collision>
    <inertial>
      <origin xyz="0 0 0" rpy="0 0 0"/>
      <mass value="10.0"/>
      <inertia ixx="0.133" ixy="0.0" ixz="0.0" iyy="0.208" iyz="0.0" izz="0.275"/>
    </inertial>
  </link>

  <!-- Base footprint (for navigation) -->
  <link name="base_footprint"/>
  
  <joint name="base_joint" type="fixed">
    <parent link="base_footprint"/>
    <child link="base_link"/>
    <origin xyz="0.0 0.0 ${wheel_radius}" rpy="0 0 0"/>
  </joint>

  <!-- Mecanum wheels macro -->
  <xacro:macro name="mecanum_wheel" params="prefix reflect_x reflect_y">
    <link name="${prefix}_wheel">
      <visual>
        <origin xyz="0 0 0" rpy="${pi/2} 0 0"/>
        <geometry>
          <cylinder radius="${wheel_radius}" length="${wheel_width}"/>
        </geometry>
        <material name="black"/>
      </visual>
      <collision>
        <origin xyz="0 0 0" rpy="${pi/2} 0 0"/>
        <geometry>
          <cylinder radius="${wheel_radius}" length="${wheel_width}"/>
        </geometry>
      </collision>
      <inertial>
        <origin xyz="0 0 0" rpy="${pi/2} 0 0"/>
        <mass value="1.0"/>
        <inertia ixx="0.0052" ixy="0.0" ixz="0.0" iyy="0.0052" iyz="0.0" izz="0.01"/>
      </inertial>
    </link>
    
    <joint name="${prefix}_wheel_joint" type="continuous">
      <parent link="base_link"/>
      <child link="${prefix}_wheel"/>
      <origin xyz="${reflect_x * wheel_offset_x} ${reflect_y * wheel_offset_y} ${-base_height/2}" rpy="0 0 0"/>
      <axis xyz="0 1 0"/>
    </joint>
  </xacro:macro>

  <!-- Create all four mecanum wheels -->
  <xacro:mecanum_wheel prefix="front_left" reflect_x="1" reflect_y="1"/>
  <xacro:mecanum_wheel prefix="front_right" reflect_x="1" reflect_y="-1"/>
  <xacro:mecanum_wheel prefix="rear_left" reflect_x="-1" reflect_y="1"/>
  <xacro:mecanum_wheel prefix="rear_right" reflect_x="-1" reflect_y="-1"/>

  <!-- Lidar mount -->
  <link name="lidar_link">
    <visual>
      <origin xyz="0 0 0" rpy="0 0 0"/>
      <geometry>
        <cylinder radius="0.05" length="0.1"/>
      </geometry>
      <material name="red"/>
    </visual>
    <collision>
      <origin xyz="0 0 0" rpy="0 0 0"/>
      <geometry>
        <cylinder radius="0.05" length="0.1"/>
      </geometry>
    </collision>
    <inertial>
      <origin xyz="0 0 0" rpy="0 0 0"/>
      <mass value="0.5"/>
      <inertia ixx="0.002" ixy="0.0" ixz="0.0" iyy="0.002" iyz="0.0" izz="0.00125"/>
    </inertial>
  </link>

  <joint name="lidar_joint" type="fixed">
    <parent link="base_link"/>
    <child link="lidar_link"/>
    <origin xyz="0.15 0 ${base_height/2 + 0.05}" rpy="0 0 0"/>
  </joint>

</robot>
